Workbook

Sheet Lisez-moi
A1: ControlDOne — Modèle financier 12 mois : mode d'emploi
A3: TOUS LES CHIFFRES DE CE CLASSEUR SONT DES HYPOTHÈSES, PAS DES PRÉVISIONS.
A4: ControlDOne est en pré-lancement : aucun client, aucun chiffre d'affaires, aucune traction à ce jour. Ce modèle sert à tester la cohérence d'une idée, pas à annoncer un résultat.
A6: Comment l'utiliser
A7: 1. Feuille « Modèle », cellule B3 : choisir le scénario (prudent / central / ambitieux) dans la liste.
A8: 2. Feuille « Hypothèses » : modifier les cellules jaunes à texte bleu (ce sont les seules entrées). La colonne F montre la valeur utilisée pour le scénario choisi.
A9: 3. La rampe des diagnostics vendus par mois se modifie mois par mois, scénario par scénario.
A10: 4. Coût d'IA : 0 € par dossier aujourd'hui (extraction déterministe). Pour simuler un LLM, mettre « Extracteur LLM activé » à 1 et choisir le modèle ; le coût par dossier se calcule à partir des prix catalogue 2026 par million de jetons.
A11: 5. Toute la feuille « Modèle » est en formules : ne pas y saisir de valeurs, sauf la cellule du scénario et le seuil de viabilité.
A13: Ce que calcule le modèle
A14: Revenus par flux (diagnostic 390 €, abonnement à partir de 99 €/mois, commission 20 % des avoirs obtenus), coûts variables (Stripe, IA), coûts fixes (hébergement, domaine, RC Pro, comptabilité, plateforme agréée), marge brute, résultat mensuel, trésorerie cumulée, mois d'équilibre (avec et sans rémunération théorique du fondateur), heures nécessaires et capacité.
A16: Simplifications assumées
... A26: Version : 2 octobre 2026. Fichier généré avec openpyxl ; formules vérifiées par recalcul LibreOffice.

Sheet Hypothèses
A1: ControlDOne — Hypothèses du modèle 12 mois (toutes les valeurs sont des HYPOTHÈSES, pas des prévisions)
A2: Cellules jaunes à texte bleu = entrées modifiables. Colonne F = valeur utilisée par la feuille « Modèle » selon le scénario choisi en Modèle!B3. Prix de départ (diagnostic 390 €, commission 20 %, abonnement 99 €/mois) : valeurs de lancement fixées par le fondateur (docs/SPEC.md §1.1).
A4: Paramètre | B4: prudent | C4: central | D4: ambitieux | E4: Unité | F4: Valeur active | G4: Source / statut
A5: Revenus
A6: Prix du diagnostic (forfait) | B6: 390 | C6: 390 | D6: 390 | E6: € HT | F6: =INDEX(B6:D6,1,Modèle!$B$4) -> 390 | G6: Prix de lancement du fondateur (SPEC §1.1) ; repère : les cabinets au résultat facturent souvent ~5 000 € minimum (Compass Financement)
A7: Prix de l'abonnement « contrôle continu » | B7: 99 | C7: 99 | D7: 99 | E7: € HT / mois | F7: =INDEX(B7:D7,1,Modèle!$B$4) -> 99 | G7: Prix de lancement « à partir de 99 €/mois » (SPEC §1.1)
A8: Taux de commission sur avoirs obtenus | B8: 0.2 | C8: 0.2 | D8: 0.2 | E8: % | F8: =INDEX(B8:D8,1,Modèle!$B$4) -> 0.2 | G8: Prix de lancement (SPEC §1.1) ; repère : Ownwell prend 25–35 % des économies de taxe foncière obtenues (Crunchbase News)
A9: Conversion diagnostic → abonnement | B9: 0.15 | C9: 0.25 | D9: 0.4 | E9: % | F9: =INDEX(B9:D9,1,Modèle!$B$4) -> 0.25 | G9: hypothèse du fondateur à valider
A10: Avoirs obtenus par diagnostic (dossiers passés, une fois) | B10: 300 | C10: 800 | D10: 1500 | E10: € / diagnostic | F10: =INDEX(B10:D10,1,Modèle!$B$4) -> 800 | G10: hypothèse du fondateur à valider. Aucune mesure indépendante des taux d'erreur des factures transitaires (2 % à 30 % selon les éditeurs)
A11: Avoirs obtenus par abonné et par mois | B11: 50 | C11: 150 | D11: 300 | E11: € / abonné / mois | F11: =INDEX(B11:D11,1,Modèle!$B$4) -> 150 | G11: hypothèse du fondateur à valider. Repère : la viabilité en solo suppose ≥ 3 000–4 000 € trouvés par client et par an (calcul propre de l'auteur)
A12: Délai entre constat et avoir encaissé | B12: 3 | C12: 2 | D12: 2 | E12: mois | F12: =INDEX(B12:D12,1,Modèle!$B$4) -> 2 | G12: hypothèse du fondateur à valider (le client réclame lui-même, SPEC §1.2 P-3)
A13: Attrition mensuelle des abonnés | B13: 0.08 | C13: 0.05 | D13: 0.03 | E13: % / mois | F13: =INDEX(B13:D13,1,Modèle!$B$4) -> 0.05 | G13: hypothèse du fondateur à valider. Contexte : les apps d'IA perdent leurs payants 30 % plus vite (RevenueCat, State of Subscription Apps 2026)
A14: Volumes de travail
A15: Dossiers analysés par diagnostic | B15: 20 | C15: 20 | D15: 20 | E15: dossiers | F15: =INDEX(B15:D15,1,Modèle!$B$4) -> 20 | G15: hypothèse du fondateur à valider
A16: Dossiers contrôlés par abonné et par mois | B16: 8 | C16: 10 | D16: 12 | E16: dossiers / mois | F16: =INDEX(B16:D16,1,Modèle!$B$4) -> 10 | G16: hypothèse du fondateur à valider
A17: Coûts
A18: Hébergement UE bas coût | B18: 20 | C18: 10 | D18: 10 | E18: € HT / mois | F18: =INDEX(B18:D18,1,Modèle!$B$4) -> 10 | G18: Fourchette ~0,43 € (Scaleway STARDUST1-S) à 19,99 € HT (OVHcloud VPS-3) par mois, cf. docs/recherche/legal_market.md §6 ; choix dans la fourchette = hypothèse du fondateur à valider
A19: Nom de domaine | B19: 2 | C19: 1.25 | D19: 1.25 | E19: € / mois | F19: =INDEX(B19:D19,1,Modèle!$B$4) -> 1.25 | G19: hypothèse du fondateur à valider (~15–24 €/an)
A20: Assurance RC Pro | B20: 25 | C20: 13 | D20: 13 | E20: € / mois | F20: =INDEX(B20:D20,1,Modèle!$B$4) -> 13 | G20: Hiscox : à partir de 13 €/mois (central/ambitieux) ; prudent 25 € = hypothèse du fondateur à valider
A21: Frais Stripe (part variable) | B21: 0.022 | C21: 0.02 | D21: 0.02 | E21: % du CA encaissé | F21: =INDEX(B21:D21,1,Modèle!$B$4) -> 0.02 | G21: hypothèse du fondateur à valider — à vérifier sur stripe.com/fr/pricing (cartes UE + Stripe Billing)
A22: Frais Stripe (part fixe par transaction) | B22: 0.25 | C22: 0.25 | D22: 0.25 | E22: € / transaction | F22: =INDEX(B22:D22,1,Modèle!$B$4) -> 0.25 | G22: hypothèse du fondateur à valider — à vérifier sur stripe.com/fr/pricing
A23: Expert-comptable / outil comptable | B23: 100 | C23: 70 | D23: 70 | E23: € HT / mois | F23: =INDEX(B23:D23,1,Modèle!$B$4) -> 70 | G23: hypothèse du fondateur à valider
A24: Plateforme agréée de facturation électronique (PA) | B24: 25 | C24: 15 | D24: 15 | E24: € HT / mois | F24: =INDEX(B24:D24,1,Modèle!$B$4) -> 15 | G24: hypothèse du fondateur à valider. Réception obligatoire depuis le 1er sept. 2026, émission PME au plus tard le 1er sept. 2027 (economie.gouv.fr ; docs/recherche/einvoice.md)
A25: Trésorerie de départ | B25: 0 | C25: 0 | D25: 0 | E25: € | F25: =INDEX(B25:D25,1,Modèle!$B$4) -> 0 | G25: hypothèse du fondateur à valider
A26: Temps du fondateur (seul, à temps partiel)
A27: Heures disponibles par mois | B27: 40 | C27: 40 | D27: 60 | E27: h / mois | F27: =INDEX(B27:D27,1,Modèle!$B$4) -> 40 | G27: hypothèse du fondateur à valider
A28: Heures par diagnostic (validation, rapport, échange) | B28: 6 | C28: 4 | D28: 3 | E28: h / diagnostic | F28: =INDEX(B28:D28,1,Modèle!$B$4) -> 4 | G28: hypothèse du fondateur à valider
A29: Heures par abonné et par mois | B29: 1.5 | C29: 1 | D29: 0.75 | E29: h / abonné / mois | F29: =INDEX(B29:D29,1,Modèle!$B$4) -> 1 | G29: hypothèse du fondateur à valider
A30: Heures fixes d'administration et prospection | B30: 10 | C30: 8 | D30: 8 | E30: h / mois | F30: =INDEX(B30:D30,1,Modèle!$B$4) -> 8 | G30: hypothèse du fondateur à valider
A31: Rémunération horaire théorique du fondateur (non versée) | B31: 35 | C31: 35 | D31: 35 | E31: € / h | F31: =INDEX(B31:D31,1,Modèle!$B$4) -> 35 | G31: hypothèse du fondateur à valider — sert uniquement à un second seuil d'équilibre
A33: Rampe : diagnostics vendus par mois (hypothèse du fondateur à valider)
A34: Scénario \ mois | B34: M1 | C34: M2 | D34: M3 | E34: M4 | F34: M5 | G34: M6 | H34: M7 | I34: M8 | J34: M9 | K34: M10 | L34: M11 | M34: M12 | N34: Total
A35: prudent | B35: 0 | C35: 1 | D35: 1 | E35: 1 | F35: 2 | G35: 2 | H35: 2 | I35: 2 | J35: 3 | K35: 3 | L35: 3 | M35: 3 | N35: =SUM(B35:M35) -> 23
A36: central | B36: 1 | C36: 1 | D36: 2 | E36: 2 | F36: 3 | G36: 3 | H36: 4 | I36: 4 | J36: 4 | K36: 5 | L36: 5 | M36: 5 | N36: =SUM(B36:M36) -> 39
A37: ambitieux | B37: 1 | C37: 2 | D37: 3 | E37: 4 | F37: 5 | G37: 6 | H37: 6 | I37: 7 | J37: 8 | K37: 8 | L37: 9 | M37: 10 | N37: =SUM(B37:M37) -> 69
A39: Paramètres communs à tous les scénarios : coût d'IA par dossier
A40: Paramètre | B40: Valeur | E40: Unité | G40: Source / statut
A41: Extracteur LLM activé ? (0 = non, 1 = oui) | B41: 0 | E41: 0/1 | G41: État actuel : 0. L'extraction est déterministe (règles + texte PDF/OCR), coût d'IA = 0 € par dossier (docs/SPEC.md P-4, docs/DECISIONS.md D-018)
A42: Modèle utilisé si LLM activé | B42: claude-sonnet-5-5 | E42: nom | G42: hypothèse du fondateur à valider (liste déroulante)
A43: Jetons d'entrée par dossier | B43: 25000 | E43: jetons | G43: hypothèse du fondateur à valider (~4 documents de 2–3 pages + consignes)
...

Sheet Modèle
A1: ControlDOne — Modèle 12 mois (scénarios d'HYPOTHÈSES, pas une prévision)
A3: Scénario choisi (liste) : | B3: central | D3: ← choisir prudent / central / ambitieux ; toutes les lignes ci-dessous se recalculent.
A4: Index du scénario (calculé) | B4: =MATCH(B3,Hypothèses!$B$4:$D$4,0) -> 2
A6: Mois | B6: 1 | C6: 2 | D6: 3 | E6: 4 | F6: 5 | G6: 6 | H6: 7 | I6: 8 | J6: 9 | K6: 10 | L6: 11 | M6: 12 | N6: Total / fin
A8: Volumes
A9: Diagnostics vendus | B9: =INDEX(Hypothèses!B$35:B$37,$B$4,1) -> 1 | C9: =INDEX(Hypothèses!C$35:C$37,$B$4,1) -> 1 | D9: =INDEX(Hypothèses!D$35:D$37,$B$4,1) -> 2 | E9: =INDEX(Hypothèses!E$35:E$37,$B$4,1) -> 2 | F9: =INDEX(Hypothèses!F$35:F$37,$B$4,1) -> 3 | G9: =INDEX(Hypothèses!G$35:G$37,$B$4,1) -> 3 | H9: =INDEX(Hypothèses!H$35:H$37,$B$4,1) -> 4 | I9: =INDEX(Hypothèses!I$35:I$37,$B$4,1) -> 4 | ... M9: =INDEX(Hypothèses!M$35:M$37,$B$4,1) -> 5 | N9: =SUM(B9:M9) -> 39
A10: Nouveaux abonnés (diagnostics × conversion) | B10: =B9*Hypothèses!$F$9 -> 0.25 | C10: =C9*Hypothèses!$F$9 -> 0.25 | D10: =D9*Hypothèses!$F$9 -> 0.5 | E10: =E9*Hypothèses!$F$9 -> 0.5 | F10: =F9*Hypothèses!$F$9 -> 0.75 | G10: =G9*Hypothèses!$F$9 -> 0.75 | H10: =H9*Hypothèses!$F$9 -> 1 | I10: =I9*Hypothèses!$F$9 -> 1 | ... M10: =M9*Hypothèses!$F$9 -> 1.25 | N10: =SUM(B10:M10) -> 9.75
A11: Abonnés en début de mois | B11: =0 -> 0 | C11: =B13 -> 0.25 | D11: =C13 -> 0.4875 | E11: =D13 -> 0.963125 | F11: =E13 -> 1.4149688 | G11: =F13 -> 2.0942203 | H11: =G13 -> 2.7395093 | I11: =H13 -> 3.6025338 | J11: =I13 -> 4.4224071 | ... M11: =L13 -> 7.1316613
A12: Départs (attrition) | B12: =B11*Hypothèses!$F$13 -> 0 | C12: =C11*Hypothèses!$F$13 -> 0.0125 | D12: =D11*Hypothèses!$F$13 -> 0.024375 | E12: =E11*Hypothèses!$F$13 -> 0.04815625 | F12: =F11*Hypothèses!$F$13 -> 0.070748437 | G12: =G11*Hypothèses!$F$13 -> 0.10471102 | H12: =H11*Hypothèses!$F$13 -> 0.13697546 | I12: =I11*Hypothèses!$F$13 -> 0.18012669 | ... M12: =M11*Hypothèses!$F$13 -> 0.35658307 | N12: =SUM(B12:M12) -> 1.7249217
A13: Abonnés en fin de mois | B13: =B11+B10-B12 -> 0.25 | C13: =C11+C10-C12 -> 0.4875 | D13: =D11+D10-D12 -> 0.963125 | E13: =E11+E10-E12 -> 1.4149688 | F13: =F11+F10-F12 -> 2.0942203 | G13: =G11+G10-G12 -> 2.7395093 | H13: =H11+H10-H12 -> 3.6025338 | I13: =I11+I10-I12 -> 4.4224071 | ... M13: =M11+M10-M12 -> 8.0250783 | N13: =M13 -> 8.0250783
A14: Dossiers traités | B14: =B9*Hypothèses!$F$15+B13*Hypothèses!$F$16 -> 22.5 | C14: =C9*Hypothèses!$F$15+C13*Hypothèses!$F$16 -> 24.875 | D14: =D9*Hypothèses!$F$15+D13*Hypothèses!$F$16 -> 49.63125 | E14: =E9*Hypothèses!$F$15+E13*Hypothèses!$F$16 -> 54.149687 | F14: =F9*Hypothèses!$F$15+F13*Hypothèses!$F$16 -> 80.942203 | G14: =G9*Hypothèses!$F$15+G13*Hypothèses!$F$16 -> 87.395093 | H14: =H9*Hypothèses!$F$15+H13*Hypothèses!$F$16 -> 116.02534 | I14: =I9*Hypothèses!$F$15+I13*Hypothèses!$F$16 -> 124.22407 | ... M14: =M9*Hypothèses!$F$15+M13*Hypothèses!$F$16 -> 180.25078 | N14: =SUM(B14:M14) -> 1205.2351
A16: Avoirs obtenus par les clients (pour mémoire, base de la commission)
A17: Avoirs issus des diagnostics (avec délai) | B17: =IF(B$6-Hypothèses!$F$12>=1,INDEX($B$9:$M$9,1,B$6-Hypothèses!$F$12),0)*Hypothèses!$F$10 -> 0 | C17: =IF(C$6-Hypothèses!$F$12>=1,INDEX($B$9:$M$9,1,C$6-Hypothèses!$F$12),0)*Hypothèses!$F$10 -> 0 | D17: =IF(D$6-Hypothèses!$F$12>=1,INDEX($B$9:$M$9,1,D$6-Hypothèses!$F$12),0)*Hypothèses!$F$10 -> 800 | E17: =IF(E$6-Hypothèses!$F$12>=1,INDEX($B$9:$M$9,1,E$6-Hypothèses!$F$12),0)*Hypothèses!$F$10 -> 800 | F17: =IF(F$6-Hypothèses!$F$12>=1,INDEX($B$9:$M$9,1,F$6-Hypothèses!$F$12),0)*Hypothèses!$F$10 -> 1600 | G17: =IF(G$6-Hypothèses!$F$12>=1,INDEX($B$9:$M$9,1,G$6-Hypothèses!$F$12),0)*Hypothèses!$F$10 -> 1600 | H17: =IF(H$6-Hypothèses!$F$12>=1,INDEX($B$9:$M$9,1,H$6-Hypothèses!$F$12),0)*Hypothèses!$F$10 -> 2400 | I17: =IF(I$6-Hypothèses!$F$12>=1,INDEX($B$9:$M$9,1,I$6-Hypothèses!$F$12),0)*Hypothèses!$F$10 -> 2400 | ... M17: =IF(M$6-Hypothèses!$F$12>=1,INDEX($B$9:$M$9,1,M$6-Hypothèses!$F$12),0)*Hypothèses!$F$10 -> 4000 | N17: =SUM(B17:M17) -> 23200
A18: Avoirs issus du contrôle continu (avec délai) | B18: =IF(B$6-Hypothèses!$F$12>=1,INDEX($B$13:$M$13,1,B$6-Hypothèses!$F$12),0)*Hypothèses!$F$11 -> 0 | C18: =IF(C$6-Hypothèses!$F$12>=1,INDEX($B$13:$M$13,1,C$6-Hypothèses!$F$12),0)*Hypothèses!$F$11 -> 0 | D18: =IF(D$6-Hypothèses!$F$12>=1,INDEX($B$13:$M$13,1,D$6-Hypothèses!$F$12),0)*Hypothèses!$F$11 -> 37.5 | E18: =IF(E$6-Hypothèses!$F$12>=1,INDEX($B$13:$M$13,1,E$6-Hypothèses!$F$12),0)*Hypothèses!$F$11 -> 73.125 | F18: =IF(F$6-Hypothèses!$F$12>=1,INDEX($B$13:$M$13,1,F$6-Hypothèses!$F$12),0)*Hypothèses!$F$11 -> 144.46875 | G18: =IF(G$6-Hypothèses!$F$12>=1,INDEX($B$13:$M$13,1,G$6-Hypothèses!$F$12),0)*Hypothèses!$F$11 -> 212.24531 | H18: =IF(H$6-Hypothèses!$F$12>=1,INDEX($B$13:$M$13,1,H$6-Hypothèses!$F$12),0)*Hypothèses!$F$11 -> 314.13305 | I18: =IF(I$6-Hypothèses!$F$12>=1,INDEX($B$13:$M$13,1,I$6-Hypothèses!$F$12),0)*Hypothèses!$F$11 -> 410.92639 | ... M18: =IF(M$6-Hypothèses!$F$12>=1,INDEX($B$13:$M$13,1,M$6-Hypothèses!$F$12),0)*Hypothèses!$F$11 -> 928.68337 | N18: =SUM(B18:M18) -> 4105.016
A20: Revenus par flux (€ HT)
A21: Diagnostics | B21: =B9*Hypothèses!$F$6 -> 390 | C21: =C9*Hypothèses!$F$6 -> 390 | D21: =D9*Hypothèses!$F$6 -> 780 | E21: =E9*Hypothèses!$F$6 -> 780 | F21: =F9*Hypothèses!$F$6 -> 1170 | G21: =G9*Hypothèses!$F$6 -> 1170 | H21: =H9*Hypothèses!$F$6 -> 1560 | I21: =I9*Hypothèses!$F$6 -> 1560 | ... M21: =M9*Hypothèses!$F$6 -> 1950 | N21: =SUM(B21:M21) -> 15210
A22: Abonnements | B22: =B13*Hypothèses!$F$7 -> 24.75 | C22: =C13*Hypothèses!$F$7 -> 48.2625 | D22: =D13*Hypothèses!$F$7 -> 95.349375 | E22: =E13*Hypothèses!$F$7 -> 140.08191 | F22: =F13*Hypothèses!$F$7 -> 207.32781 | G22: =G13*Hypothèses!$F$7 -> 271.21142 | H22: =H13*Hypothèses!$F$7 -> 356.65085 | I22: =I13*Hypothèses!$F$7 -> 437.81831 | ... M22: =M13*Hypothèses!$F$7 -> 794.48275 | N22: =SUM(B22:M22) -> 4209.8278
A23: Commission sur avoirs | B23: =(B17+B18)*Hypothèses!$F$8 -> 0 | C23: =(C17+C18)*Hypothèses!$F$8 -> 0 | D23: =(D17+D18)*Hypothèses!$F$8 -> 167.5 | E23: =(E17+E18)*Hypothèses!$F$8 -> 174.625 | F23: =(F17+F18)*Hypothèses!$F$8 -> 348.89375 | G23: =(G17+G18)*Hypothèses!$F$8 -> 362.44906 | H23: =(H17+H18)*Hypothèses!$F$8 -> 542.82661 | I23: =(I17+I18)*Hypothèses!$F$8 -> 562.18528 | ... M23: =(M17+M18)*Hypothèses!$F$8 -> 985.73667 | N23: =SUM(B23:M23) -> 5461.0032
A24: Total revenus | B24: =B21+B22+B23 -> 414.75 | C24: =C21+C22+C23 -> 438.2625 | D24: =D21+D22+D23 -> 1042.8494 | E24: =E21+E22+E23 -> 1094.7069 | F24: =F21+F22+F23 -> 1726.2216 | G24: =G21+G22+G23 -> 1803.6605 | H24: =H21+H22+H23 -> 2459.4775 | I24: =I21+I22+I23 -> 2560.0036 | ... M24: =M21+M22+M23 -> 3730.2194 | N24: =SUM(B24:M24) -> 24880.831
A26: Coûts variables
A27: Frais Stripe | B27: =B24*Hypothèses!$F$21+(B9+B13)*Hypothèses!$F$22 -> 8.6075 | C27: =C24*Hypothèses!$F$21+(C9+C13)*Hypothèses!$F$22 -> 9.137125 | D27: =D24*Hypothèses!$F$21+(D9+D13)*Hypothèses!$F$22 -> 21.597769 | E27: =E24*Hypothèses!$F$21+(E9+E13)*Hypothèses!$F$22 -> 22.74788 | F27: =F24*Hypothèses!$F$21+(F9+F13)*Hypothèses!$F$22 -> 35.797986 | G27: =G24*Hypothèses!$F$21+(G9+G13)*Hypothèses!$F$22 -> 37.508087 | H27: =H24*Hypothèses!$F$21+(H9+H13)*Hypothèses!$F$22 -> 51.090183 | I27: =I24*Hypothèses!$F$21+(I9+I13)*Hypothèses!$F$22 -> 53.305674 | ... M27: =M24*Hypothèses!$F$21+(M9+M13)*Hypothèses!$F$22 -> 77.860658 | N27: =SUM(B27:M27) -> 517.9975
A28: Coût d'IA (dossiers × coût par dossier) | B28: =B14*Hypothèses!$B$52 -> 0 | C28: =C14*Hypothèses!$B$52 -> 0 | D28: =D14*Hypothèses!$B$52 -> 0 | E28: =E14*Hypothèses!$B$52 -> 0 | F28: =F14*Hypothèses!$B$52 -> 0 | G28: =G14*Hypothèses!$B$52 -> 0 | H28: =H14*Hypothèses!$B$52 -> 0 | I28: =I14*Hypothèses!$B$52 -> 0 | ... M28: =M14*Hypothèses!$B$52 -> 0 | N28: =SUM(B28:M28) -> 0
A29: Total coûts variables | B29: =B27+B28 -> 8.6075 | C29: =C27+C28 -> 9.137125 | D29: =D27+D28 -> 21.597769 | E29: =E27+E28 -> 22.74788 | F29: =F27+F28 -> 35.797986 | G29: =G27+G28 -> 37.508087 | H29: =H27+H28 -> 51.090183 | I29: =I27+I28 -> 53.305674 | ... M29: =M27+M28 -> 77.860658 | N29: =SUM(B29:M29) -> 517.9975
A30: Marge brute | B30: =B24-B29 -> 406.1425 | C30: =C24-C29 -> 429.12538 | D30: =D24-D29 -> 1021.2516 | E30: =E24-E29 -> 1071.959 | F30: =F24-F29 -> 1690.4236 | G30: =G24-G29 -> 1766.1524 | H30: =H24-H29 -> 2408.3873 | I30: =I24-I29 -> 2506.6979 | ... M30: =M24-M29 -> 3652.3588 | N30: =SUM(B30:M30) -> 24362.834
A31: Taux de marge brute | B31: =IF(B24>0,B30/B24,0) -> 0.97924653 | C31: =IF(C24>0,C30/C24,0) -> 0.97915148 | D31: =IF(D24>0,D30/D24,0) -> 0.97928966 | E31: =IF(E24>0,E30/E24,0) -> 0.97922012 | F31: =IF(F24>0,F30/F24,0) -> 0.97926223 | G31: =IF(G24>0,G30/G24,0) -> 0.97920446 | H31: =IF(H24>0,H30/H24,0) -> 0.97922722 | I31: =IF(I24>0,I30/I24,0) -> 0.9791775 | ... N31: =IF(N24>0,N30/N24,0) -> 0.97918086
A33: Coûts fixes
A34: Hébergement | B34: =Hypothèses!$F$18 -> 10 | C34: =Hypothèses!$F$18 -> 10 | D34: =Hypothèses!$F$18 -> 10 | E34: =Hypothèses!$F$18 -> 10 | F34: =Hypothèses!$F$18 -> 10 | G34: =Hypothèses!$F$18 -> 10 | H34: =Hypothèses!$F$18 -> 10 | I34: =Hypothèses!$F$18 -> 10 | ... M34: =Hypothèses!$F$18 -> 10 | N34: =SUM(B34:M34) -> 120
A35: Nom de domaine | B35: =Hypothèses!$F$19 -> 1.25 | C35: =Hypothèses!$F$19 -> 1.25 | D35: =Hypothèses!$F$19 -> 1.25 | E35: =Hypothèses!$F$19 -> 1.25 | F35: =Hypothèses!$F$19 -> 1.25 | G35: =Hypothèses!$F$19 -> 1.25 | H35: =Hypothèses!$F$19 -> 1.25 | I35: =Hypothèses!$F$19 -> 1.25 | ... M35: =Hypothèses!$F$19 -> 1.25 | N35: =SUM(B35:M35) -> 15
A36: Assurance RC Pro | B36: =Hypothèses!$F$20 -> 13 | C36: =Hypothèses!$F$20 -> 13 | D36: =Hypothèses!$F$20 -> 13 | E36: =Hypothèses!$F$20 -> 13 | F36: =Hypothèses!$F$20 -> 13 | G36: =Hypothèses!$F$20 -> 13 | H36: =Hypothèses!$F$20 -> 13 | I36: =Hypothèses!$F$20 -> 13 | ... M36: =Hypothèses!$F$20 -> 13 | N36: =SUM(B36:M36) -> 156
A37: Comptabilité | B37: =Hypothèses!$F$23 -> 70 | C37: =Hypothèses!$F$23 -> 70 | D37: =Hypothèses!$F$23 -> 70 | E37: =Hypothèses!$F$23 -> 70 | F37: =Hypothèses!$F$23 -> 70 | G37: =Hypothèses!$F$23 -> 70 | H37: =Hypothèses!$F$23 -> 70 | I37: =Hypothèses!$F$23 -> 70 | ... M37: =Hypothèses!$F$23 -> 70 | N37: =SUM(B37:M37) -> 840
A38: Plateforme agréée (PA) | B38: =Hypothèses!$F$24 -> 15 | C38: =Hypothèses!$F$24 -> 15 | D38: =Hypothèses!$F$24 -> 15 | E38: =Hypothèses!$F$24 -> 15 | F38: =Hypothèses!$F$24 -> 15 | G38: =Hypothèses!$F$24 -> 15 | H38: =Hypothèses!$F$24 -> 15 | I38: =Hypothèses!$F$24 -> 15 | ... M38: =Hypothèses!$F$24 -> 15 | N38: =SUM(B38:M38) -> 180
A39: Total coûts fixes | B39: =SUM(B34:B38) -> 109.25 | C39: =SUM(C34:C38) -> 109.25 | D39: =SUM(D34:D38) -> 109.25 | E39: =SUM(E34:E38) -> 109.25 | F39: =SUM(F34:F38) -> 109.25 | G39: =SUM(G34:G38) -> 109.25 | H39: =SUM(H34:H38) -> 109.25 | I39: =SUM(I34:I38) -> 109.25 | ... M39: =SUM(M34:M38) -> 109.25 | N39: =SUM(B39:M39) -> 1311
A41: Résultat et trésorerie
A42: Résultat mensuel (avant rémunération du fondateur) | B42: =B30-B39 -> 296.8925 | C42: =C30-C39 -> 319.87538 | D42: =D30-D39 -> 912.00161 | E42: =E30-E39 -> 962.70903 | F42: =F30-F39 -> 1581.1736 | G42: =G30-G39 -> 1656.9024 | H42: =H30-H39 -> 2299.1373 | I42: =I30-I39 -> 2397.4479 | ... M42: =M30-M39 -> 3543.1088 | N42: =SUM(B42:M42) -> 23051.834
A43: Trésorerie cumulée | B43: =Hypothèses!$F$25+B42 -> 296.8925 | C43: =B43+C42 -> 616.76788 | D43: =C43+D42 -> 1528.7695 | E43: =D43+E42 -> 2491.4785 | F43: =E43+F42 -> 4072.6521 | G43: =F43+G42 -> 5729.5545 | H43: =G43+H42 -> 8028.6918 | I43: =H43+I42 -> 10426.14 | J43: =I43+J42 -> 13081.133 | ... M43: =L43+M42 -> 23051.834 | N43: =M43 -> 23051.834
A45: Temps du fondateur
A46: Heures nécessaires | B46: =B9*Hypothèses!$F$28+B13*Hypothèses!$F$29+Hypothèses!$F$30 -> 12.25 | C46: =C9*Hypothèses!$F$28+C13*Hypothèses!$F$29+Hypothèses!$F$30 -> 12.4875 | D46: =D9*Hypothèses!$F$28+D13*Hypothèses!$F$29+Hypothèses!$F$30 -> 16.963125 | E46: =E9*Hypothèses!$F$28+E13*Hypothèses!$F$29+Hypothèses!$F$30 -> 17.414969 | F46: =F9*Hypothèses!$F$28+F13*Hypothèses!$F$29+Hypothèses!$F$30 -> 22.09422 | G46: =G9*Hypothèses!$F$28+G13*Hypothèses!$F$29+Hypothèses!$F$30 -> 22.739509 | H46: =H9*Hypothèses!$F$28+H13*Hypothèses!$F$29+Hypothèses!$F$30 -> 27.602534 | I46: =I9*Hypothèses!$F$28+I13*Hypothèses!$F$29+Hypothèses!$F$30 -> 28.422407 | ... M46: =M9*Hypothèses!$F$28+M13*Hypothèses!$F$29+Hypothèses!$F$30 -> 36.025078 | N46: =SUM(B46:M46) -> 294.52351
A47: Heures disponibles | B47: =Hypothèses!$F$27 -> 40 | C47: =Hypothèses!$F$27 -> 40 | D47: =Hypothèses!$F$27 -> 40 | E47: =Hypothèses!$F$27 -> 40 | F47: =Hypothèses!$F$27 -> 40 | G47: =Hypothèses!$F$27 -> 40 | H47: =Hypothèses!$F$27 -> 40 | I47: =Hypothèses!$F$27 -> 40 | ... M47: =Hypothèses!$F$27 -> 40 | N47: =SUM(B47:M47) -> 480
A48: Capacité dépassée ? | B48: =IF(B46>B47,"OUI","non") -> non | C48: =IF(C46>C47,"OUI","non") -> non | D48: =IF(D46>D47,"OUI","non") -> non | E48: =IF(E46>E47,"OUI","non") -> non | F48: =IF(F46>F47,"OUI","non") -> non | G48: =IF(G46>G47,"OUI","non") -> non | H48: =IF(H46>H47,"OUI","non") -> non | I48: =IF(I46>I47,"OUI","non") -> non | ... M48: =IF(M46>M47,"OUI","non") -> non | N48: =IF(COUNTIF(B48:M48,"OUI")>0,"OUI","non") -> non
A49: Rémunération théorique (heures × taux, non versée) | B49: =B46*Hypothèses!$F$31 -> 428.75 | C49: =C46*Hypothèses!$F$31 -> 437.0625 | D49: =D46*Hypothèses!$F$31 -> 593.70938 | E49: =E46*Hypothèses!$F$31 -> 609.52391 | F49: =F46*Hypothèses!$F$31 -> 773.29771 | G49: =G46*Hypothèses!$F$31 -> 795.88283 | H49: =H46*Hypothèses!$F$31 -> 966.08868 | I49: =I46*Hypothèses!$F$31 -> 994.78425 | ... M49: =M46*Hypothèses!$F$31 -> 1260.8777 | N49: =SUM(B49:M49) -> 10308.323
...
